Watching for file changes with StatReloader
Internal Server Error: /admin/cake/product/add/
Traceback (most recent call last):
  File "C:\Users\admin\Documents\GitHub\cakewalk\venv\Lib\site-packages\django\db\backends\base\base.py", line 313, in _commit
    return self.connection.commit()
           ^^^^^^^^^^^^^^^^^^^^^^^^
sqlite3.IntegrityError: FOREIGN KEY constraint failed

The above exception was the direct cause of the following exception:

Traceback (most recent call last):
  File "C:\Users\admin\Documents\GitHub\cakewalk\venv\Lib\site-packages\django\core\handlers\exception.py", line 55, in inner
    response = get_response(request)
               ^^^^^^^^^^^^^^^^^^^^^
  File "C:\Users\admin\Documents\GitHub\cakewalk\venv\Lib\site-packages\django\core\handlers\base.py", line 197, in _get_response
    response = wrapped_callback(request, *callback_args, **callback_kwargs)
               ^^^^^^^^^^^^^^^^^^^^^^^^^^^^^^^^^^^^^^^^^^^^^^^^^^^^^^^^^^^^
  File "C:\Users\admin\Documents\GitHub\cakewalk\venv\Lib\site-packages\django\contrib\admin\options.py", line 688, in wrapper
    return self.admin_site.admin_view(view)(*args, **kwargs)
           ^^^^^^^^^^^^^^^^^^^^^^^^^^^^^^^^^^^^^^^^^^^^^^^^^
  File "C:\Users\admin\Documents\GitHub\cakewalk\venv\Lib\site-packages\django\utils\decorators.py", line 134, in _wrapper_view
    response = view_func(request, *args, **kwargs)
               ^^^^^^^^^^^^^^^^^^^^^^^^^^^^^^^^^^^
  File "C:\Users\admin\Documents\GitHub\cakewalk\venv\Lib\site-packages\django\views\decorators\cache.py", line 62, in _wrapper_view_func
    response = view_func(request, *args, **kwargs)
               ^^^^^^^^^^^^^^^^^^^^^^^^^^^^^^^^^^^
  File "C:\Users\admin\Documents\GitHub\cakewalk\venv\Lib\site-packages\django\contrib\admin\sites.py", line 242, in inner
    return view(request, *args, **kwargs)
           ^^^^^^^^^^^^^^^^^^^^^^^^^^^^^^
  File "C:\Users\admin\Documents\GitHub\cakewalk\venv\Lib\site-packages\django\contrib\admin\options.py", line 1886, in add_view
    return self.changeform_view(request, None, form_url, extra_context)
           ^^^^^^^^^^^^^^^^^^^^^^^^^^^^^^^^^^^^^^^^^^^^^^^^^^^^^^^^^^^^
  File "C:\Users\admin\Documents\GitHub\cakewalk\venv\Lib\site-packages\django\utils\decorators.py", line 46, in _wrapper
    return bound_method(*args, **kwargs)
           ^^^^^^^^^^^^^^^^^^^^^^^^^^^^^
  File "C:\Users\admin\Documents\GitHub\cakewalk\venv\Lib\site-packages\django\utils\decorators.py", line 134, in _wrapper_view
    response = view_func(request, *args, **kwargs)
               ^^^^^^^^^^^^^^^^^^^^^^^^^^^^^^^^^^^
  File "C:\Users\admin\Documents\GitHub\cakewalk\venv\Lib\site-packages\django\contrib\admin\options.py", line 1746, in changeform_view
    with transaction.atomic(using=router.db_for_write(self.model)):
  File "C:\Users\admin\Documents\GitHub\cakewalk\venv\Lib\site-packages\django\db\transaction.py", line 263, in __exit__
    connection.commit()
  File "C:\Users\admin\Documents\GitHub\cakewalk\venv\Lib\site-packages\django\utils\asyncio.py", line 26, in inner
    return func(*args, **kwargs)
           ^^^^^^^^^^^^^^^^^^^^^
  File "C:\Users\admin\Documents\GitHub\cakewalk\venv\Lib\site-packages\django\db\backends\base\base.py", line 337, in commit
    self._commit()
  File "C:\Users\admin\Documents\GitHub\cakewalk\venv\Lib\site-packages\django\db\backends\base\base.py", line 312, in _commit
    with debug_transaction(self, "COMMIT"), self.wrap_database_errors:
  File "C:\Users\admin\Documents\GitHub\cakewalk\venv\Lib\site-packages\django\db\utils.py", line 91, in __exit__
    raise dj_exc_value.with_traceback(traceback) from exc_value
  File "C:\Users\admin\Documents\GitHub\cakewalk\venv\Lib\site-packages\django\db\backends\base\base.py", line 313, in _commit
    return self.connection.commit()
           ^^^^^^^^^^^^^^^^^^^^^^^^
django.db.utils.IntegrityError: FOREIGN KEY constraint failed
Watching for file changes with StatReloader
C:\Users\admin\Documents\GitHub\cakewalk\cake\models.py changed, reloading.
Watching for file changes with StatReloader
C:\Users\admin\Documents\GitHub\cakewalk\cake\models.py changed, reloading.
Watching for file changes with StatReloader
C:\Users\admin\Documents\GitHub\cakewalk\cake\models.py changed, reloading.
Watching for file changes with StatReloader
C:\Users\admin\Documents\GitHub\cakewalk\cake\models.py changed, reloading.
Watching for file changes with StatReloader
C:\Users\admin\Documents\GitHub\cakewalk\cake\models.py changed, reloading.
Watching for file changes with StatReloader
Watching for file changes with StatReloader
Importing BlpImagePlugin
Importing BmpImagePlugin
Importing BufrStubImagePlugin
Importing CurImagePlugin
Importing DcxImagePlugin
Importing DdsImagePlugin
Importing EpsImagePlugin
Importing FitsImagePlugin
Importing FliImagePlugin
Importing FpxImagePlugin
Image: failed to import FpxImagePlugin: No module named 'olefile'
Importing FtexImagePlugin
Importing GbrImagePlugin
Importing GifImagePlugin
Importing GribStubImagePlugin
Importing Hdf5StubImagePlugin
Importing IcnsImagePlugin
Importing IcoImagePlugin
Importing ImImagePlugin
Importing ImtImagePlugin
Importing IptcImagePlugin
Importing JpegImagePlugin
Importing Jpeg2KImagePlugin
Importing McIdasImagePlugin
Importing MicImagePlugin
Image: failed to import MicImagePlugin: No module named 'olefile'
Importing MpegImagePlugin
Importing MpoImagePlugin
Importing MspImagePlugin
Importing PalmImagePlugin
Importing PcdImagePlugin
Importing PcxImagePlugin
Importing PdfImagePlugin
Importing PixarImagePlugin
Importing PngImagePlugin
Importing PpmImagePlugin
Importing PsdImagePlugin
Importing QoiImagePlugin
Importing SgiImagePlugin
Importing SpiderImagePlugin
Importing SunImagePlugin
Importing TgaImagePlugin
Importing TiffImagePlugin
Importing WebPImagePlugin
Importing WmfImagePlugin
Importing XbmImagePlugin
Importing XpmImagePlugin
Importing XVThumbImagePlugin
Not Found: /favicon.ico
STREAM b'IHDR' 16 13
STREAM b'pHYs' 41 9
STREAM b'sRGB' 62 1
STREAM b'gAMA' 75 4
STREAM b'IDAT' 91 47625
STREAM b'IHDR' 16 13
STREAM b'pHYs' 41 9
STREAM b'sRGB' 62 1
STREAM b'gAMA' 75 4
STREAM b'IDAT' 91 47625
Internal Server Error: /admin/cake/product/add/
Traceback (most recent call last):
  File "C:\Users\admin\Documents\GitHub\cakewalk\venv\Lib\site-packages\django\db\backends\base\base.py", line 313, in _commit
    return self.connection.commit()
           ^^^^^^^^^^^^^^^^^^^^^^^^
sqlite3.IntegrityError: FOREIGN KEY constraint failed

The above exception was the direct cause of the following exception:

Traceback (most recent call last):
  File "C:\Users\admin\Documents\GitHub\cakewalk\venv\Lib\site-packages\django\core\handlers\exception.py", line 55, in inner
    response = get_response(request)
               ^^^^^^^^^^^^^^^^^^^^^
  File "C:\Users\admin\Documents\GitHub\cakewalk\venv\Lib\site-packages\django\core\handlers\base.py", line 197, in _get_response
    response = wrapped_callback(request, *callback_args, **callback_kwargs)
               ^^^^^^^^^^^^^^^^^^^^^^^^^^^^^^^^^^^^^^^^^^^^^^^^^^^^^^^^^^^^
  File "C:\Users\admin\Documents\GitHub\cakewalk\venv\Lib\site-packages\django\contrib\admin\options.py", line 688, in wrapper
    return self.admin_site.admin_view(view)(*args, **kwargs)
           ^^^^^^^^^^^^^^^^^^^^^^^^^^^^^^^^^^^^^^^^^^^^^^^^^
  File "C:\Users\admin\Documents\GitHub\cakewalk\venv\Lib\site-packages\django\utils\decorators.py", line 134, in _wrapper_view
    response = view_func(request, *args, **kwargs)
               ^^^^^^^^^^^^^^^^^^^^^^^^^^^^^^^^^^^
  File "C:\Users\admin\Documents\GitHub\cakewalk\venv\Lib\site-packages\django\views\decorators\cache.py", line 62, in _wrapper_view_func
    response = view_func(request, *args, **kwargs)
               ^^^^^^^^^^^^^^^^^^^^^^^^^^^^^^^^^^^
  File "C:\Users\admin\Documents\GitHub\cakewalk\venv\Lib\site-packages\django\contrib\admin\sites.py", line 242, in inner
    return view(request, *args, **kwargs)
           ^^^^^^^^^^^^^^^^^^^^^^^^^^^^^^
  File "C:\Users\admin\Documents\GitHub\cakewalk\venv\Lib\site-packages\django\contrib\admin\options.py", line 1886, in add_view
    return self.changeform_view(request, None, form_url, extra_context)
           ^^^^^^^^^^^^^^^^^^^^^^^^^^^^^^^^^^^^^^^^^^^^^^^^^^^^^^^^^^^^
  File "C:\Users\admin\Documents\GitHub\cakewalk\venv\Lib\site-packages\django\utils\decorators.py", line 46, in _wrapper
    return bound_method(*args, **kwargs)
           ^^^^^^^^^^^^^^^^^^^^^^^^^^^^^
  File "C:\Users\admin\Documents\GitHub\cakewalk\venv\Lib\site-packages\django\utils\decorators.py", line 134, in _wrapper_view
    response = view_func(request, *args, **kwargs)
               ^^^^^^^^^^^^^^^^^^^^^^^^^^^^^^^^^^^
  File "C:\Users\admin\Documents\GitHub\cakewalk\venv\Lib\site-packages\django\contrib\admin\options.py", line 1746, in changeform_view
    with transaction.atomic(using=router.db_for_write(self.model)):
  File "C:\Users\admin\Documents\GitHub\cakewalk\venv\Lib\site-packages\django\db\transaction.py", line 263, in __exit__
    connection.commit()
  File "C:\Users\admin\Documents\GitHub\cakewalk\venv\Lib\site-packages\django\utils\asyncio.py", line 26, in inner
    return func(*args, **kwargs)
           ^^^^^^^^^^^^^^^^^^^^^
  File "C:\Users\admin\Documents\GitHub\cakewalk\venv\Lib\site-packages\django\db\backends\base\base.py", line 337, in commit
    self._commit()
  File "C:\Users\admin\Documents\GitHub\cakewalk\venv\Lib\site-packages\django\db\backends\base\base.py", line 312, in _commit
    with debug_transaction(self, "COMMIT"), self.wrap_database_errors:
  File "C:\Users\admin\Documents\GitHub\cakewalk\venv\Lib\site-packages\django\db\utils.py", line 91, in __exit__
    raise dj_exc_value.with_traceback(traceback) from exc_value
  File "C:\Users\admin\Documents\GitHub\cakewalk\venv\Lib\site-packages\django\db\backends\base\base.py", line 313, in _commit
    return self.connection.commit()
           ^^^^^^^^^^^^^^^^^^^^^^^^
django.db.utils.IntegrityError: FOREIGN KEY constraint failed
C:\Users\admin\Documents\GitHub\cakewalk\cakewalk\settings.py changed, reloading.
